Workbook

Sheet listes
A1: id | B1: catégories | C1: id | D1: cycles | E1: id | F1: niveaux | G1: id | H1: années | I1: id | J1: spécialités | K1: id | L1: matières
A2: CAT001 | B2: école & études | C2: EEE001 | D2: primaire | E2: NIV001 | F2: CP | G2: ANN001 | H2: bac+1 | I2: SPE001 | J2: Chartes | K2: MAT001 | L2: français
A3: CAT002 | B3: langues | C3: EEE002 | D3: collège | E3: NIV002 | F3: CE1 | G3: ANN002 | H3: bac+2 | I3: SPE002 | J3: lettres | K3: MAT002 | L3: mathématiques
A4: CAT003 | B4: professionnel | C4: EEE003 | D4: lycée | E4: NIV003 | F4: CE2 | G4: ANN003 | H4: bac+3 | I4: SPE003 | J4: lettres et sciences sociales | K4: MAT003 | L4: questionner le monde
A5: CAT004 | B5: culture générale | C5: EEE004 | D5: études supérieures | E5: NIV004 | F5: CM1 | G5: ANN004 | H5: bac+4 | I5: SPE004 | J5: Saint-Cyr lettres | K5: MAT004 | L5: anglais
A6: CAT005 | B6: personnel | E6: NIV005 | F6: CM2 | G6: ANN005 | H6: bac+5 | I6: SPE005 | J6: arts et design | K6: MAT005 | L6: éducation artistique
E7: NIV006 | F7: 6ème | G7: ANN006 | H7: bac+6 | I7: SPE006 | J7: BCPST | K7: MAT006 | L7: éducation physique
E8: NIV007 | F8: 5ème | G8: ANN007 | H8: bac+7 | I8: SPE007 | J8: MP2I | K8: MAT007 | L8: histoire
E9: NIV008 | F9: 4ème | G9: ANN008 | H9: bac+8 | I9: SPE008 | J9: MPSI | K9: MAT008 | L9: géographie
E10: NIV009 | F10: 3ème | G10: ANN009 | H10: bac+9 | I10: SPE009 | J10: PCSI | K10: MAT009 | L10: sciences
E11: NIV010 | F11: 2nde | G11: ANN010 | H11: bac+10 | I11: SPE010 | J11: PTSI | K11: MAT010 | L11: EMC
E12: NIV011 | F12: 1ère | G12: ANN011 | H12: bac+11 | I12: SPE011 | J12: architecture | K12: MAT011 | L12: SVT
E13: NIV012 | F13: terminale | G13: ANN012 | H13: bac+12 | I13: SPE012 | J13: arts | K13: MAT012 | L13: physique
E14: NIV013 | F14: BTS | I14: SPE013 | J14: audiovisuel | K14: MAT013 | L14: chimie
E15: NIV014 | F15: BTSA | I15: SPE014 | J15: musique et danse | K15: MAT014 | L15: technologie
E16: NIV015 | F16: BUT | I16: SPE015 | J16: comédie et théatre | K16: MAT015 | L16: arts plastiques
E17: NIV016 | F17: CPGE | I17: SPE016 | J17: cirque et mime | K17: MAT016 | L17: éducation musicale
E18: NIV017 | F18: école d'ingénieurs | I18: SPE017 | K18: MAT017 | L18: EPS
E19: NIV018 | F19: école de commerce | I19: SPE018 | K19: MAT018 | L19: SES
E20: NIV019 | F20: licence | I20: SPE019 | K20: MAT019 | L20: SNT
E21: NIV020 | F21: master | I21: SPE020 | K21: MAT020 | L21: NSI
E22: NIV021 | F22: DE (diplôme d'état) | I22: SPE021 | J22: 2nde générale et technologique | K22: MAT021 | L22: sciences de l'ingénieur
E23: NIV022 | F23: DN MADE | I23: SPE022 | J23: voie générale | K23: MAT022 | L23: HGGSP
E24: NIV023 | F24: DNA | I24: SPE023 | J24: STMG | K24: MAT023 | L24: HLP
E25: NIV024 | F25: non diplomant | I25: SPE024 | J25: STI2D | K25: MAT024 | L25: LLCER
E26: NIV025 | F26: DNSP | I26: SPE025 | J26: STL | K26: MAT025 | L26: LLCA
E27: NIV026 | F27: doctorat | I27: SPE026 | J27: ST2S | K27: MAT026 | L27: Arts
E28: NIV027 | F28: licence professionnelle | I28: SPE027 | J28: STD2A | K28: MAT027 | L28: éducation physique, pratiques et culture sportives
E29: NIV028 | F29: DEUST | I29: SPE028 | J29: STHR | K29: MAT028 | L29: philosophie
E30: NIV029 | F30: Diplôme d'école | I30: SPE029 | J30: S2TMD | K30: MAT029 | L30: DGEMC
E31: NIV030 | F31: DSAA | I31: SPE030 | J31: STAV | K31: MAT030 | L31: latin
E32: NIV031 | F32: DCG | I32: SPE031 | J32: bac pro – production | K32: MAT031 | L32: grec ancien
E33: NIV032 | F33: bachelor agro | I33: SPE032 | J33: bac pro – services | K33: MAT032 | L33: littérature française
... E37: NIV036 | F37: DSCG | I37: SPE036 | J37: PC | K37: MAT036 | L37: économie
I38: SPE037 | J38: PSI | K38: MAT037 | L38: sociologie
I39: SPE038 | J39: PT | K39: MAT038 | L39: géopolitique
I40: SPE039 | J40: TSI | K40: MAT039 | L40: design
I41: SPE040 | J41: TB | K41: MAT040 | L41: histoire de l'art
I42: SPE041 | J42: ATS | K42: MAT041 | L42: biologie
I43: SPE042 | J43: ECG | K43: MAT042 | L43: géologie
...

Sheet catégorie-cycles
C1: {=TRANSPOSE(listes!A2:B12)} -> CAT001 | D1: CAT002 | E1: CAT003 | F1: CAT004 | G1: CAT005 | H1: 0 | I1: 0 | J1: 0 | K1: 0 | L1: 0 | M1: 0
A2: =IF(listes!C1="","",listes!C1) -> id | B2: =IF(listes!D1="","",listes!D1) -> cycles | C2: école & études | D2: langues | E2: professionnel | F2: culture générale | G2: personnel | H2: 0 | I2: 0 | J2: 0 | K2: 0 | L2: 0 | M2: 0
A3: =IF(listes!C2="","",listes!C2) -> EEE001 | B3: =IF(listes!D2="","",listes!D2) -> primaire | C3: 1
A4: =IF(listes!C3="","",listes!C3) -> EEE002 | B4: =IF(listes!D3="","",listes!D3) -> collège | C4: 1
A5: =IF(listes!C4="","",listes!C4) -> EEE003 | B5: =IF(listes!D4="","",listes!D4) -> lycée | C5: 1
A6: =IF(listes!C5="","",listes!C5) -> EEE004 | B6: =IF(listes!D5="","",listes!D5) -> études supérieures | C6: 1

Sheet cycles-niveaux
C1: {=TRANSPOSE(listes!C2:D11)} -> EEE001 | D1: EEE002 | E1: EEE003 | F1: EEE004 | G1: 0 | H1: 0 | I1: 0 | J1: 0 | K1: 0 | L1: 0
A2: =IF(listes!E1="","",listes!E1) -> id | B2: =IF(listes!F1="","",listes!F1) -> niveaux | C2: primaire | D2: collège | E2: lycée | F2: études supérieures | G2: 0 | H2: 0 | I2: 0 | J2: 0 | K2: 0 | L2: 0
A3: =IF(listes!E2="","",listes!E2) -> NIV001 | B3: =IF(listes!F2="","",listes!F2) -> CP | C3: 1
A4: =IF(listes!E3="","",listes!E3) -> NIV002 | B4: =IF(listes!F3="","",listes!F3) -> CE1 | C4: 1
A5: =IF(listes!E4="","",listes!E4) -> NIV003 | B5: =IF(listes!F4="","",listes!F4) -> CE2 | C5: 1
A6: =IF(listes!E5="","",listes!E5) -> NIV004 | B6: =IF(listes!F5="","",listes!F5) -> CM1 | C6: 1
A7: =IF(listes!E6="","",listes!E6) -> NIV005 | B7: =IF(listes!F6="","",listes!F6) -> CM2 | C7: 1
A8: =IF(listes!E7="","",listes!E7) -> NIV006 | B8: =IF(listes!F7="","",listes!F7) -> 6ème | D8: 1
A9: =IF(listes!E8="","",listes!E8) -> NIV007 | B9: =IF(listes!F8="","",listes!F8) -> 5ème | D9: 1
A10: =IF(listes!E9="","",listes!E9) -> NIV008 | B10: =IF(listes!F9="","",listes!F9) -> 4ème | D10: 1
A11: =IF(listes!E10="","",listes!E10) -> NIV009 | B11: =IF(listes!F10="","",listes!F10) -> 3ème | D11: 1
A12: =IF(listes!E11="","",listes!E11) -> NIV010 | B12: =IF(listes!F11="","",listes!F11) -> 2nde | E12: 1
A13: =IF(listes!E12="","",listes!E12) -> NIV011 | B13: =IF(listes!F12="","",listes!F12) -> 1ère | E13: 1
A14: =IF(listes!E13="","",listes!E13) -> NIV012 | B14: =IF(listes!F13="","",listes!F13) -> terminale | E14: 1
A15: =IF(listes!E14="","",listes!E14) -> NIV013 | B15: =IF(listes!F14="","",listes!F14) -> BTS | F15: 1
A16: =IF(listes!E15="","",listes!E15) -> NIV014 | B16: =IF(listes!F15="","",listes!F15) -> BTSA | F16: 1
A17: =IF(listes!E16="","",listes!E16) -> NIV015 | B17: =IF(listes!F16="","",listes!F16) -> BUT | F17: 1
A18: =IF(listes!E17="","",listes!E17) -> NIV016 | B18: =IF(listes!F17="","",listes!F17) -> CPGE | F18: 1
A19: =IF(listes!E18="","",listes!E18) -> NIV017 | B19: =IF(listes!F18="","",listes!F18) -> école d'ingénieurs | F19: 1
A20: =IF(listes!E19="","",listes!E19) -> NIV018 | B20: =IF(listes!F19="","",listes!F19) -> école de commerce | F20: 1
A21: =IF(listes!E20="","",listes!E20) -> NIV019 | B21: =IF(listes!F20="","",listes!F20) -> licence | F21: 1
A22: =IF(listes!E21="","",listes!E21) -> NIV020 | B22: =IF(listes!F21="","",listes!F21) -> master | F22: 1
A23: =IF(listes!E22="","",listes!E22) -> NIV021 | B23: =IF(listes!F22="","",listes!F22) -> DE (diplôme d'état) | F23: 1
A24: =IF(listes!E23="","",listes!E23) -> NIV022 | B24: =IF(listes!F23="","",listes!F23) -> DN MADE | F24: 1
A25: =IF(listes!E24="","",listes!E24) -> NIV023 | B25: =IF(listes!F24="","",listes!F24) -> DNA | F25: 1
A26: =IF(listes!E25="","",listes!E25) -> NIV024 | B26: =IF(listes!F25="","",listes!F25) -> non diplomant | F26: 1
... A35: =IF(listes!E34="","",listes!E34) -> NIV033 | B35: =IF(listes!F34="","",listes!F34) -> bachelor | F35: 1
A36: =IF(listes!E35="","",listes!E35) -> NIV034 | B36: =IF(listes!F35="","",listes!F35) -> CAP | E36: 1
A37: =IF(listes!E36="","",listes!E36) -> NIV035 | B37: =IF(listes!F36="","",listes!F36) -> PASS | F37: 1
A38: =IF(listes!E37="","",listes!E37) -> NIV036 | B38: =IF(listes!F37="","",listes!F37) -> DSCG | F38: 1

Sheet niveaux-spécialités
C1: {=TRANSPOSE(listes!E2:F43)} -> NIV001 | D1: NIV002 | E1: NIV003 | F1: NIV004 | G1: NIV005 | H1: NIV006 | I1: NIV007 | J1: NIV008 | K1: NIV009 | L1: NIV010 | M1: NIV011 | N1: NIV012 | O1: NIV013 | P1: NIV014 | Q1: NIV015 | R1: NIV016 | S1: NIV017 | T1: NIV018 | U1: NIV019 | V1: NIV020 | W1: NIV021 | X1: NIV022 | Y1: NIV023 | Z1: NIV024 | AA1: NIV025 | AB1: NIV026 | AC1: NIV027 | AD1: NIV028 | AE1: NIV029 | AF1: NIV030 | AG1: NIV031 | AH1: NIV032 | AI1: NIV033 | AJ1: NIV034 | AK1: NIV035 | AL1: NIV036 | AM1: 0 | AN1: 0 | AO1: 0 | AP1: 0 | AQ1: 0 | AR1: 0
A2: =IF(listes!I1="","",listes!I1) -> id | B2: =IF(listes!J1="","",listes!J1) -> spécialités | C2: CP | D2: CE1 | E2: CE2 | F2: CM1 | G2: CM2 | H2: 6ème | I2: 5ème | J2: 4ème | K2: 3ème | L2: 2nde | M2: 1ère | N2: terminale | O2: BTS | P2: BTSA | Q2: BUT | R2: CPGE | S2: école d'ingénieurs | T2: école de commerce | U2: licence | V2: master | W2: DE (diplôme d'état) | X2: DN MADE | Y2: DNA | Z2: non diplomant | AA2: DNSP | AB2: doctorat | AC2: licence professionnelle | AD2: DEUST | AE2: Diplôme d'école | AF2: DSAA | AG2: DCG | AH2: bachelor agro | AI2: bachelor | AJ2: CAP | AK2: PASS | AL2: DSCG | AM2: 0 | AN2: 0 | AO2: 0 | AP2: 0 | AQ2: 0 | AR2: 0
A3: =IF(listes!I2="","",listes!I2) -> SPE001 | B3: =IF(listes!J2="","",listes!J2) -> Chartes | R3: 1
A4: =IF(listes!I3="","",listes!I3) -> SPE002 | B4: =IF(listes!J3="","",listes!J3) -> lettres | R4: 1 | U4: 1 | V4: 1 | AB4: 1
A5: =IF(listes!I4="","",listes!I4) -> SPE003 | B5: =IF(listes!J4="","",listes!J4) -> lettres et sciences sociales | R5: 1
A6: =IF(listes!I5="","",listes!I5) -> SPE004 | B6: =IF(listes!J5="","",listes!J5) -> Saint-Cyr lettres | R6: 1
A7: =IF(listes!I6="","",listes!I6) -> SPE005 | B7: =IF(listes!J6="","",listes!J6) -> arts et design | R7: 1
A8: =IF(listes!I7="","",listes!I7) -> SPE006 | B8: =IF(listes!J7="","",listes!J7) -> BCPST | R8: 1
A9: =IF(listes!I8="","",listes!I8) -> SPE007 | B9: =IF(listes!J8="","",listes!J8) -> MP2I | R9: 1
A10: =IF(listes!I9="","",listes!I9) -> SPE008 | B10: =IF(listes!J9="","",listes!J9) -> MPSI | R10: 1
A11: =IF(listes!I10="","",listes!I10) -> SPE009 | B11: =IF(listes!J10="","",listes!J10) -> PCSI | R11: 1
A12: =IF(listes!I11="","",listes!I11) -> SPE010 | B12: =IF(listes!J11="","",listes!J11) -> PTSI | R12: 1
A13: =IF(listes!I12="","",listes!I12) -> SPE011 | B13: =IF(listes!J12="","",listes!J12) -> architecture | V13: 1 | W13: 1 | AB13: 1
A14: =IF(listes!I13="","",listes!I13) -> SPE012 | B14: =IF(listes!J13="","",listes!J13) -> arts | U14: 1 | V14: 1 | X14: 1 | Y14: 1 | AB14: 1
A15: =IF(listes!I14="","",listes!I14) -> SPE013 | B15: =IF(listes!J14="","",listes!J14) -> audiovisuel | O15: 1 | Q15: 1 | U15: 1 | V15: 1 | AE15: 1
A16: =IF(listes!I15="","",listes!I15) -> SPE014 | B16: =IF(listes!J15="","",listes!J15) -> musique et danse | U16: 1 | V16: 1 | W16: 1 | AA16: 1
A17: =IF(listes!I16="","",listes!I16) -> SPE015 | B17: =IF(listes!J16="","",listes!J16) -> comédie et théatre | U17: 1 | V17: 1 | AA17: 1 | AE17: 1
A18: =IF(listes!I17="","",listes!I17) -> SPE016 | B18: =IF(listes!J17="","",listes!J17) -> cirque et mime | AA18: 1
A19: =IF(listes!I18="","",listes!I18) -> SPE017 | B19: =IF(listes!J18="","",listes!J18)
A20: =IF(listes!I19="","",listes!I19) -> SPE018 | B20: =IF(listes!J19="","",listes!J19)
A21: =IF(listes!I20="","",listes!I20) -> SPE019 | B21: =IF(listes!J20="","",listes!J20)
A22: =IF(listes!I21="","",listes!I21) -> SPE020 | B22: =IF(listes!J21="","",listes!J21)
A23: =IF(listes!I22="","",listes!I22) -> SPE021 | B23: =IF(listes!J22="","",listes!J22) -> 2nde générale et technologique | L23: 1
A24: =IF(listes!I23="","",listes!I23) -> SPE022 | B24: =IF(listes!J23="","",listes!J23) -> voie générale | M24: 1 | N24: 1
A25: =IF(listes!I24="","",listes!I24) -> SPE023 | B25: =IF(listes!J24="","",listes!J24) -> STMG | M25: 1 | N25: 1
A26: =IF(listes!I25="","",listes!I25) -> SPE024 | B26: =IF(listes!J25="","",listes!J25) -> STI2D | M26: 1 | N26: 1
A27: =IF(listes!I26="","",listes!I26) -> SPE025 | B27: =IF(listes!J26="","",listes!J26) -> STL | M27: 1 | N27: 1
A28: =IF(listes!I27="","",listes!I27) -> SPE026 | B28: =IF(listes!J27="","",listes!J27) -> ST2S | M28: 1 | N28: 1
A29: =IF(listes!I28="","",listes!I28) -> SPE027 | B29: =IF(listes!J28="","",listes!J28) -> STD2A | M29: 1 | N29: 1
A30: =IF(listes!I29="","",listes!I29) -> SPE028 | B30: =IF(listes!J29="","",listes!J29) -> STHR | M30: 1 | N30: 1
A31: =IF(listes!I30="","",listes!I30) -> SPE029 | B31: =IF(listes!J30="","",listes!J30) -> S2TMD | M31: 1 | N31: 1
A32: =IF(listes!I31="","",listes!I31) -> SPE030 | B32: =IF(listes!J31="","",listes!J31) -> STAV | M32: 1 | N32: 1
A33: =IF(listes!I32="","",listes!I32) -> SPE031 | B33: =IF(listes!J32="","",listes!J32) -> bac pro – production | L33: 1 | M33: 1 | N33: 1
A34: =IF(listes!I33="","",listes!I33) -> SPE032 | B34: =IF(listes!J33="","",listes!J33) -> bac pro – services | L34: 1 | M34: 1 | N34: 1
A35: =IF(listes!I34="","",listes!I34) -> SPE033 | B35: =IF(listes!J34="","",listes!J34) -> CAP | AJ35: 1
A36: =IF(listes!I35="","",listes!I35) -> SPE034 | B36: =IF(listes!J35="","",listes!J35) -> MP | R36: 1
A37: =IF(listes!I36="","",listes!I36) -> SPE035 | B37: =IF(listes!J36="","",listes!J36) -> MPI | R37: 1
A38: =IF(listes!I37="","",listes!I37) -> SPE036 | B38: =IF(listes!J37="","",listes!J37) -> PC | R38: 1
A39: =IF(listes!I38="","",listes!I38) -> SPE037 | B39: =IF(listes!J38="","",listes!J38) -> PSI | R39: 1
A40: =IF(listes!I39="","",listes!I39) -> SPE038 | B40: =IF(listes!J39="","",listes!J39) -> PT | R40: 1
...

Sheet niveaux-années
C1: {=TRANSPOSE(listes!E2:F43)} -> NIV001 | D1: NIV002 | E1: NIV003 | F1: NIV004 | G1: NIV005 | H1: NIV006 | I1: NIV007 | J1: NIV008 | K1: NIV009 | L1: NIV010 | M1: NIV011 | N1: NIV012 | O1: NIV013 | P1: NIV014 | Q1: NIV015 | R1: NIV016 | S1: NIV017 | T1: NIV018 | U1: NIV019 | V1: NIV020 | W1: NIV021 | X1: NIV022 | Y1: NIV023 | Z1: NIV024 | AA1: NIV025 | AB1: NIV026 | AC1: NIV027 | AD1: NIV028 | AE1: NIV029 | AF1: NIV030 | AG1: NIV031 | AH1: NIV032 | AI1: NIV033 | AJ1: NIV034 | AK1: NIV035 | AL1: NIV036 | AM1: 0 | AN1: 0 | AO1: 0 | AP1: 0 | AQ1: 0 | AR1: 0
A2: =IF(listes!G1="","",listes!G1) -> id | B2: =IF(listes!H1="","",listes!H1) -> années | C2: CP | D2: CE1 | E2: CE2 | F2: CM1 | G2: CM2 | H2: 6ème | I2: 5ème | J2: 4ème | K2: 3ème | L2: 2nde | M2: 1ère | N2: terminale | O2: BTS | P2: BTSA | Q2: BUT | R2: CPGE | S2: école d'ingénieurs | T2: école de commerce | U2: licence | V2: master | W2: DE (diplôme d'état) | X2: DN MADE | Y2: DNA | Z2: non diplomant | AA2: DNSP | AB2: doctorat | AC2: licence professionnelle | AD2: DEUST | AE2: Diplôme d'école | AF2: DSAA | AG2: DCG | AH2: bachelor agro | AI2: bachelor | AJ2: CAP | AK2: PASS | AL2: DSCG | AM2: 0 | AN2: 0 | AO2: 0 | AP2: 0 | AQ2: 0 | AR2: 0
A3: =IF(listes!G2="","",listes!G2) -> ANN001 | B3: =IF(listes!H2="","",listes!H2) -> bac+1 | O3: 1 | P3: 1 | Q3: 1 | R3: 1 | S3: 1 | T3: 1 | U3: 1 | W3: 1 | X3: 1 | Y3: 1 | AA3: 1 | AD3: 1 | AE3: 1 | AG3: 1 | AH3: 1 | AI3: 1 | AK3: 1
A4: =IF(listes!G3="","",listes!G3) -> ANN002 | B4: =IF(listes!H3="","",listes!H3) -> bac+2 | O4: 1 | P4: 1 | Q4: 1 | R4: 1 | S4: 1 | T4: 1 | U4: 1 | W4: 1 | X4: 1 | Y4: 1 | AA4: 1 | AD4: 1 | AE4: 1 | AG4: 1 | AH4: 1 | AI4: 1
A5: =IF(listes!G4="","",listes!G4) -> ANN003 | B5: =IF(listes!H4="","",listes!H4) -> bac+3 | Q5: 1 | S5: 1 | T5: 1 | U5: 1 | W5: 1 | X5: 1 | Y5: 1 | AA5: 1 | AC5: 1 | AE5: 1 | AG5: 1 | AH5: 1 | AI5: 1
A6: =IF(listes!G5="","",listes!G5) -> ANN004 | B6: =IF(listes!H5="","",listes!H5) -> bac+4 | S6: 1 | T6: 1 | V6: 1 | W6: 1 | AE6: 1 | AF6: 1 | AL6: 1
A7: =IF(listes!G6="","",listes!G6) -> ANN005 | B7: =IF(listes!H6="","",listes!H6) -> bac+5 | S7: 1 | T7: 1 | V7: 1 | W7: 1 | AE7: 1 | AF7: 1 | AL7: 1
A8: =IF(listes!G7="","",listes!G7) -> ANN006 | B8: =IF(listes!H7="","",listes!H7) -> bac+6 | W8: 1 | AB8: 1
A9: =IF(listes!G8="","",listes!G8) -> ANN007 | B9: =IF(listes!H8="","",listes!H8) -> bac+7 | W9: 1 | AB9: 1
A10: =IF(listes!G9="","",listes!G9) -> ANN008 | B10: =IF(listes!H9="","",listes!H9) -> bac+8 | W10: 1 | AB10: 1
A11: =IF(listes!G10="","",listes!G10) -> ANN009 | B11: =IF(listes!H10="","",listes!H10) -> bac+9 | W11: 1
A12: =IF(listes!G11="","",listes!G11) -> ANN010 | B12: =IF(listes!H11="","",listes!H11) -> bac+10 | W12: 1
A13: =IF(listes!G12="","",listes!G12) -> ANN011 | B13: =IF(listes!H12="","",listes!H12) -> bac+11 | W13: 1
A14: =IF(listes!G13="","",listes!G13) -> ANN012 | B14: =IF(listes!H13="","",listes!H13) -> bac+12 | W14: 1

Sheet spécialités-matières
C1: {=TRANSPOSE(listes!I2:J96)} -> SPE001 | D1: SPE002 | E1: SPE003 | F1: SPE004 | G1: SPE005 | H1: SPE006 | I1: SPE007 | J1: SPE008 | K1: SPE009 | L1: SPE010 | M1: SPE011 | N1: SPE012 | O1: SPE013 | P1: SPE014 | Q1: SPE015 | R1: SPE016 | S1: SPE017 | T1: SPE018 | U1: SPE019 | V1: SPE020 | W1: SPE021 | X1: SPE022 | Y1: SPE023 | Z1: SPE024 | AA1: SPE025 | AB1: SPE026 | AC1: SPE027 | AD1: SPE028 | AE1: SPE029 | AF1: SPE030 | AG1: SPE031 | AH1: SPE032 | AI1: SPE033 | AJ1: SPE034 | AK1: SPE035 | AL1: SPE036 | AM1: SPE037 | AN1: SPE038 | AO1: SPE039 | AP1: SPE040 | AQ1: SPE041 | AR1: SPE042 | AS1: SPE043 | AT1: SPE044 | AU1: SPE045 | AV1: SPE046 | AW1: SPE047 | AX1: SPE048 | AY1: SPE049 | AZ1: SPE050 | BA1: SPE051 | BB1: SPE052 | BC1: SPE053 | BD1: SPE054 | BE1: SPE055 | BF1: SPE056 | BG1: SPE057 | BH1: SPE058 | BI1: SPE059 | BJ1: SPE060 | BK1: SPE061 | BL1: SPE062 | BM1: SPE063 | BN1: SPE064 | BO1: SPE065 | BP1: SPE066 | BQ1: SPE067 | BR1: SPE068 | BS1: SPE069 | BT1: SPE070 | BU1: SPE071 | BV1: SPE072 | BW1: SPE073 | BX1: SPE074 | BY1: SPE075 | BZ1: SPE076 | CA1: SPE077 | CB1: SPE078 | CC1: SPE079 | CD1: SPE080 | CE1: SPE081 | CF1: SPE082 | CG1: SPE083 | CH1: SPE084 | CI1: SPE085 | CJ1: SPE086 | CK1: SPE087 | CL1: SPE088 | CM1: SPE089 | CN1: 0 | CO1: 0 | CP1: 0 | CQ1: 0 | CR1: 0 | CS1: 0
A2: =IF(listes!K1="","",listes!K1) -> id | B2: =IF(listes!L1="","",listes!L1) -> matières | C2: Chartes | D2: lettres | E2: lettres et sciences sociales | F2: Saint-Cyr lettres | G2: arts et design | H2: BCPST | I2: MP2I | J2: MPSI | K2: PCSI | L2: PTSI | M2: architecture | N2: arts | O2: audiovisuel | P2: musique et danse | Q2: comédie et théatre | R2: cirque et mime | S2: 0 | T2: 0 | U2: 0 | V2: 0 | W2: 2nde générale et technologique | X2: voie générale | Y2: STMG | Z2: STI2D | AA2: STL | AB2: ST2S | AC2: STD2A | AD2: STHR | AE2: S2TMD | AF2: STAV | AG2: bac pro – production | AH2: bac pro – services | AI2: CAP | AJ2: MP | AK2: MPI | AL2: PC | AM2: PSI | AN2: PT | AO2: TSI | AP2: TB | AQ2: ATS | AR2: ECG | AS2: ECT | AT2: ENS D1 (droit-économie) | AU2: ENS D2 (économie-gestion) | AV2: accès santé (PASS / LAS) | AW2: médecine | AX2: pharmacie | AY2: odontologie | AZ2: maïeutique (sage-femme) | BA2: soins infirmiers | BB2: kinésithérapie | BC2: médecine vétérinaire | BD2: travail social | BE2: mathématiques | BF2: informatique | BG2: physique-chimie | BH2: sciences de la vie | BI2: sciences de la Terre et environnement | BJ2: génie mécanique et industriel | BK2: génie électrique et électronique | BL2: génie civil et BTP | BM2: chimie et génie des procédés | BN2: ingénierie généraliste | BO2: agronomie et agriculture | BP2: droit | BQ2: science politique | BR2: économie | BS2: gestion et management | BT2: comptabilité et finance | BU2: commerce, marketing et vente | BV2: commerce international | BW2: ressources humaines | BX2: transport et logistique | BY2: banque, assurance et immobilier | BZ2: tourisme, hôtellerie et restauration | CA2: communication et information | CB2: journalisme | CC2: langues étrangères (LLCER) | CD2: langues étrangères appliquées (LEA) | CE2: histoire | CF2: géographie et aménagement | CG2: philosophie | CH2: sociologie | CI2: psychologie | CJ2: sciences de l'éducation et enseignement (MEEF) | CK2: STAPS | CL2: design | CM2: préparation aux concours | CN2: 0 | CO2: 0 | CP2: 0 | CQ2: 0 | CR2: 0 | CS2: 0
A3: =IF(listes!K2="","",listes!K2) -> MAT001 | B3: =IF(listes!L2="","",listes!L2) -> français | C3: 1 | D3: 1 | E3: 1 | F3: 1 | G3: 1 | S3: 1 | T3: 1 | U3: 1 | V3: 1 | W3: 1 | X3: 1 | Y3: 1 | Z3: 1 | AA3: 1 | AB3: 1 | AC3: 1 | AD3: 1 | AE3: 1 | AF3: 1 | AG3: 1 | AH3: 1 | AI3: 1 | CJ3: 1
A4: =IF(listes!K3="","",listes!K3) -> MAT002 | B4: =IF(listes!L3="","",listes!L3) -> mathématiques | E4: 1 | F4: 1 | H4: 1 | I4: 1 | J4: 1 | K4: 1 | L4: 1 | S4: 1 | T4: 1 | U4: 1 | V4: 1 | W4: 1 | X4: 1 | Y4: 1 | Z4: 1 | AA4: 1 | AB4: 1 | AC4: 1 | AD4: 1 | AE4: 1 | AF4: 1 | AG4: 1 | AH4: 1 | AI4: 1 | AJ4: 1 | AK4: 1 | AL4: 1 | AM4: 1 | AN4: 1 | AO4: 1 | AP4: 1 | AQ4: 1 | AR4: 1 | AS4: 1 | AU4: 1 | BE4: 1 | BF4: 1 | BG4: 1 | BJ4: 1 | BK4: 1 | BL4: 1 | BM4: 1 | BN4: 1 | BR4: 1 | CJ4: 1
A5: =IF(listes!K4="","",listes!K4) -> MAT003 | B5: =IF(listes!L4="","",listes!L4) -> questionner le monde | S5: 1
A6: =IF(listes!K5="","",listes!K5) -> MAT004 | B6: =IF(listes!L5="","",listes!L5) -> anglais | C6: 1 | D6: 1 | E6: 1 | F6: 1 | G6: 1 | H6: 1 | I6: 1 | J6: 1 | K6: 1 | L6: 1 | M6: 1 | N6: 1 | O6: 1 | S6: 1 | T6: 1 | U6: 1 | V6: 1 | W6: 1 | X6: 1 | Y6: 1 | Z6: 1 | AA6: 1 | AB6: 1 | AC6: 1 | AD6: 1 | AE6: 1 | AF6: 1 | AG6: 1 | AH6: 1 | AI6: 1 | AJ6: 1 | AK6: 1 | AL6: 1 | AM6: 1 | AN6: 1 | AO6: 1 | AP6: 1 | AQ6: 1 | AR6: 1 | AS6: 1 | AT6: 1 | AU6: 1 | BE6: 1 | BF6: 1 | BG6: 1 | BH6: 1 | BI6: 1 | BJ6: 1 | BK6: 1 | BL6: 1 | BM6: 1 | BN6: 1 | BO6: 1 | BP6: 1 | BQ6: 1 | BR6: 1 | BS6: 1 | BT6: 1 | BU6: 1 | BV6: 1 | BW6: 1 | BX6: 1 | BY6: 1 | BZ6: 1 | CA6: 1 | CB6: 1 | CC6: 1 | CD6: 1 | CE6: 1 | CF6: 1 | CG6: 1 | CH6: 1 | CI6: 1 | CL6: 1 | CM6: 1
A7: =IF(listes!K6="","",listes!K6) -> MAT005 | B7: =IF(listes!L6="","",listes!L6) -> éducation artistique | S7: 1 | T7: 1
A8: =IF(listes!K7="","",listes!K7) -> MAT006 | B8: =IF(listes!L7="","",listes!L7) -> éducation physique | S8: 1 | T8: 1
A9: =IF(listes!K8="","",listes!K8) -> MAT007 | B9: =IF(listes!L8="","",listes!L8) -> histoire | C9: 1 | D9: 1 | E9: 1 | F9: 1 | T9: 1 | U9: 1 | V9: 1 | W9: 1 | X9: 1 | Y9: 1 | Z9: 1 | AA9: 1 | AB9: 1 | AC9: 1 | AD9: 1 | AE9: 1 | AF9: 1 | AG9: 1 | AH9: 1 | AI9: 1 | BQ9: 1 | CB9: 1 | CE9: 1
A10: =IF(listes!K9="","",listes!K9) -> MAT008 | B10: =IF(listes!L9="","",listes!L9) -> géographie | C10: 1 | D10: 1 | F10: 1 | T10: 1 | U10: 1 | V10: 1 | W10: 1 | X10: 1 | Y10: 1 | Z10: 1 | AA10: 1 | AB10: 1 | AC10: 1 | AD10: 1 | AE10: 1 | AF10: 1 | AG10: 1 | AH10: 1 | AI10: 1 | CE10: 1 | CF10: 1
A11: =IF(listes!K10="","",listes!K10) -> MAT009 | B11: =IF(listes!L10="","",listes!L10) -> sciences | T11: 1 | U11: 1
A12: =IF(listes!K11="","",listes!K11) -> MAT010 | B12: =IF(listes!L11="","",listes!L11) -> EMC | S12: 1 | T12: 1 | U12: 1 | V12: 1 | W12: 1 | X12: 1 | Y12: 1 | Z12: 1 | AA12: 1 | AB12: 1 | AC12: 1 | AD12: 1 | AE12: 1 | AF12: 1 | AG12: 1 | AH12: 1 | AI12: 1
A13: =IF(listes!K12="","",listes!K12) -> MAT011 | B13: =IF(listes!L12="","",listes!L12) -> SVT | V13: 1 | W13: 1 | X13: 1
A14: =IF(listes!K13="","",listes!K13) -> MAT012 | B14: =IF(listes!L13="","",listes!L13) -> physique | H14: 1 | I14: 1 | J14: 1 | K14: 1 | L14: 1 | V14: 1 | W14: 1 | X14: 1 | Z14: 1 | AA14: 1 | AC14: 1 | AF14: 1 | AG14: 1 | AI14: 1 | AJ14: 1 | AK14: 1 | AL14: 1 | AM14: 1 | AN14: 1 | AO14: 1 | AP14: 1 | AQ14: 1 | BG14: 1 | BI14: 1 | BK14: 1 | BN14: 1
A15: =IF(listes!K14="","",listes!K14) -> MAT013 | B15: =IF(listes!L14="","",listes!L14) -> chimie | H15: 1 | J15: 1 | K15: 1 | L15: 1 | V15: 1 | W15: 1 | X15: 1 | Z15: 1 | AA15: 1 | AB15: 1 | AC15: 1 | AF15: 1 | AG15: 1 | AI15: 1 | AJ15: 1 | AL15: 1 | AM15: 1 | AN15: 1 | AO15: 1 | AP15: 1 | AQ15: 1 | AV15: 1 | BG15: 1 | BH15: 1 | BI15: 1
A16: =IF(listes!K15="","",listes!K15) -> MAT014 | B16: =IF(listes!L15="","",listes!L15) -> technologie | U16: 1 | V16: 1
A17: =IF(listes!K16="","",listes!K16) -> MAT015 | B17: =IF(listes!L16="","",listes!L16) -> arts plastiques | G17: 1 | N17: 1 | U17: 1 | V17: 1 | AC17: 1
A18: =IF(listes!K17="","",listes!K17) -> MAT016 | B18: =IF(listes!L17="","",listes!L17) -> éducation musicale | U18: 1 | V18: 1
A19: =IF(listes!K18="","",listes!K18) -> MAT017 | B19: =IF(listes!L18="","",listes!L18) -> EPS | F19: 1 | U19: 1 | V19: 1 | W19: 1 | X19: 1 | Y19: 1 | Z19: 1 | AA19: 1 | AB19: 1 | AC19: 1 | AD19: 1 | AE19: 1 | AF19: 1 | AG19: 1 | AH19: 1 | AI19: 1
A20: =IF(listes!K19="","",listes!K19) -> MAT018 | B20: =IF(listes!L19="","",listes!L19) -> SES | W20: 1 | X20: 1
A21: =IF(listes!K20="","",listes!K20) -> MAT019 | B21: =IF(listes!L20="","",listes!L20) -> SNT | W21: 1
A22: =IF(listes!K21="","",listes!K21) -> MAT020 | B22: =IF(listes!L21="","",listes!L21) -> NSI | X22: 1
A23: =IF(listes!K22="","",listes!K22) -> MAT021 | B23: =IF(listes!L22="","",listes!L22) -> sciences de l'ingénieur | I23: 1 | J23: 1 | K23: 1 | L23: 1 | X23: 1 | AJ23: 1 | AM23: 1 | AN23: 1 | AO23: 1 | AQ23: 1
A24: =IF(listes!K23="","",listes!K23) -> MAT022 | B24: =IF(listes!L23="","",listes!L23) -> HGGSP | X24: 1
A25: =IF(listes!K24="","",listes!K24) -> MAT023 | B25: =IF(listes!L24="","",listes!L24) -> HLP | X25: 1
A26: =IF(listes!K25="","",listes!K25) -> MAT024 | B26: =IF(listes!L25="","",listes!L25) -> LLCER | X26: 1
A27: =IF(listes!K26="","",listes!K26) -> MAT025 | B27: =IF(listes!L26="","",listes!L26) -> LLCA | W27: 1 | X27: 1
A28: =IF(listes!K27="","",listes!K27) -> MAT026 | B28: =IF(listes!L27="","",listes!L27) -> Arts | X28: 1
A29: =IF(listes!K28="","",listes!K28) -> MAT027 | B29: =IF(listes!L28="","",listes!L28) -> éducation physique, pratiques et culture sportives | X29: 1 | CK29: 1
A30: =IF(listes!K29="","",listes!K29) -> MAT028 | B30: =IF(listes!L29="","",listes!L29) -> philosophie | D30: 1 | E30: 1 | F30: 1 | G30: 1 | N30: 1 | X30: 1 | Y30: 1 | Z30: 1 | AA30: 1 | AB30: 1 | AC30: 1 | AD30: 1 | AE30: 1 | AF30: 1 | CG30: 1
A31: =IF(listes!K30="","",listes!K30) -> MAT029 | B31: =IF(listes!L30="","",listes!L30) -> DGEMC | X31: 1
A32: =IF(listes!K31="","",listes!K31) -> MAT030 | B32: =IF(listes!L31="","",listes!L31) -> latin | C32: 1 | D32: 1 | V32: 1
A33: =IF(listes!K32="","",listes!K32) -> MAT031 | B33: =IF(listes!L32="","",listes!L32) -> grec ancien | C33: 1 | D33: 1 | V33: 1
A34: =IF(listes!K33="","",listes!K33) -> MAT032 | B34: =IF(listes!L33="","",listes!L33) -> littérature française | D34: 1
A35: =IF(listes!K34="","",listes!K34) -> MAT033 | B35: =IF(listes!L34="","",listes!L34) -> littérature comparée | D35: 1
A36: =IF(listes!K35="","",listes!K35) -> MAT034 | B36: =IF(listes!L35="","",listes!L35) -> langue française et stylistique | D36: 1
A37: =IF(listes!K36="","",listes!K36) -> MAT035 | B37: =IF(listes!L36="","",listes!L36) -> linguistique | D37: 1 | CC37: 1
A38: =IF(listes!K37="","",listes!K37) -> MAT036 | B38: =IF(listes!L37="","",listes!L37) -> économie | E38: 1 | AS38: 1 | AT38: 1 | AU38: 1 | BO38: 1 | BQ38: 1 | CB38: 1 | CD38: 1 | CM38: 1
A39: =IF(listes!K38="","",listes!K38) -> MAT037 | B39: =IF(listes!L38="","",listes!L38) -> sociologie | E39: 1 | BD39: 1 | BQ39: 1 | CA39: 1 | CH39: 1 | CK39: 1
A40: =IF(listes!K39="","",listes!K39) -> MAT038 | B40: =IF(listes!L39="","",listes!L39) -> géopolitique | F40: 1
...

Sheet niveaux-matières
C1: {=TRANSPOSE(listes!E2:F43)} -> NIV001 | D1: NIV002 | E1: NIV003 | F1: NIV004 | G1: NIV005 | H1: NIV006 | I1: NIV007 | J1: NIV008 | K1: NIV009 | L1: NIV010 | M1: NIV011 | N1: NIV012 | O1: NIV013 | P1: NIV014 | Q1: NIV015 | R1: NIV016 | S1: NIV017 | T1: NIV018 | U1: NIV019 | V1: NIV020 | W1: NIV021 | X1: NIV022 | Y1: NIV023 | Z1: NIV024 | AA1: NIV025 | AB1: NIV026 | AC1: NIV027 | AD1: NIV028 | AE1: NIV029 | AF1: NIV030 | AG1: NIV031 | AH1: NIV032 | AI1: NIV033 | AJ1: NIV034 | AK1: NIV035 | AL1: NIV036 | AM1: 0 | AN1: 0 | AO1: 0 | AP1: 0 | AQ1: 0 | AR1: 0
A2: =IF(listes!K1="","",listes!K1) -> id | B2: =IF(listes!L1="","",listes!L1) -> matières | C2: CP | D2: CE1 | E2: CE2 | F2: CM1 | G2: CM2 | H2: 6ème | I2: 5ème | J2: 4ème | K2: 3ème | L2: 2nde | M2: 1ère | N2: terminale | O2: BTS | P2: BTSA | Q2: BUT | R2: CPGE | S2: école d'ingénieurs | T2: école de commerce | U2: licence | V2: master | W2: DE (diplôme d'état) | X2: DN MADE | Y2: DNA | Z2: non diplomant | AA2: DNSP | AB2: doctorat | AC2: licence professionnelle | AD2: DEUST | AE2: Diplôme d'école | AF2: DSAA | AG2: DCG | AH2: bachelor agro | AI2: bachelor | AJ2: CAP | AK2: PASS | AL2: DSCG | AM2: 0 | AN2: 0 | AO2: 0 | AP2: 0 | AQ2: 0 | AR2: 0
A3: =IF(listes!K2="","",listes!K2) -> MAT001 | B3: =IF(listes!L2="","",listes!L2) -> français | C3: 1 | D3: 1 | E3: 1 | F3: 1 | G3: 1 | H3: 1 | I3: 1 | J3: 1 | K3: 1
A4: =IF(listes!K3="","",listes!K3) -> MAT002 | B4: =IF(listes!L3="","",listes!L3) -> mathématiques | C4: 1 | D4: 1 | E4: 1 | F4: 1 | G4: 1 | H4: 1 | I4: 1 | J4: 1 | K4: 1
A5: =IF(listes!K4="","",listes!K4) -> MAT003 | B5: =IF(listes!L4="","",listes!L4) -> questionner le monde | C5: 1 | D5: 1 | E5: 1
A6: =IF(listes!K5="","",listes!K5) -> MAT004 | B6: =IF(listes!L5="","",listes!L5) -> anglais | C6: 1 | D6: 1 | E6: 1 | F6: 1 | G6: 1 | H6: 1 | I6: 1 | J6: 1 | K6: 1
A7: =IF(listes!K6="","",listes!K6) -> MAT005 | B7: =IF(listes!L6="","",listes!L6) -> éducation artistique | C7: 1 | D7: 1 | E7: 1 | F7: 1 | G7: 1
A8: =IF(listes!K7="","",listes!K7) -> MAT006 | B8: =IF(listes!L7="","",listes!L7) -> éducation physique | C8: 1 | D8: 1 | E8: 1 | F8: 1 | G8: 1
A9: =IF(listes!K8="","",listes!K8) -> MAT007 | B9: =IF(listes!L8="","",listes!L8) -> histoire | F9: 1 | G9: 1 | H9: 1 | I9: 1 | J9: 1 | K9: 1
A10: =IF(listes!K9="","",listes!K9) -> MAT008 | B10: =IF(listes!L9="","",listes!L9) -> géographie | F10: 1 | G10: 1 | H10: 1 | I10: 1 | J10: 1 | K10: 1
A11: =IF(listes!K10="","",listes!K10) -> MAT009 | B11: =IF(listes!L10="","",listes!L10) -> sciences | F11: 1 | G11: 1 | H11: 1
A12: =IF(listes!K11="","",listes!K11) -> MAT010 | B12: =IF(listes!L11="","",listes!L11) -> EMC | C12: 1 | D12: 1 | E12: 1 | F12: 1 | G12: 1 | H12: 1 | I12: 1 | J12: 1 | K12: 1
A13: =IF(listes!K12="","",listes!K12) -> MAT011 | B13: =IF(listes!L12="","",listes!L12) -> SVT | I13: 1 | J13: 1 | K13: 1
A14: =IF(listes!K13="","",listes!K13) -> MAT012 | B14: =IF(listes!L13="","",listes!L13) -> physique | I14: 1 | J14: 1 | K14: 1
A15: =IF(listes!K14="","",listes!K14) -> MAT013 | B15: =IF(listes!L14="","",listes!L14) -> chimie | I15: 1 | J15: 1 | K15: 1
A16: =IF(listes!K15="","",listes!K15) -> MAT014 | B16: =IF(listes!L15="","",listes!L15) -> technologie | F16: 1 | G16: 1 | H16: 1 | I16: 1 | J16: 1 | K16: 1
A17: =IF(listes!K16="","",listes!K16) -> MAT015 | B17: =IF(listes!L16="","",listes!L16) -> arts plastiques | H17: 1 | I17: 1 | J17: 1 | K17: 1
A18: =IF(listes!K17="","",listes!K17) -> MAT016 | B18: =IF(listes!L17="","",listes!L17) -> éducation musicale | H18: 1 | I18: 1 | J18: 1 | K18: 1
A19: =IF(listes!K18="","",listes!K18) -> MAT017 | B19: =IF(listes!L18="","",listes!L18) -> EPS | H19: 1 | I19: 1 | J19: 1 | K19: 1
A20: =IF(listes!K19="","",listes!K19) -> MAT018 | B20: =IF(listes!L19="","",listes!L19) -> SES
A21: =IF(listes!K20="","",listes!K20) -> MAT019 | B21: =IF(listes!L20="","",listes!L20) -> SNT
A22: =IF(listes!K21="","",listes!K21) -> MAT020 | B22: =IF(listes!L21="","",listes!L21) -> NSI
A23: =IF(listes!K22="","",listes!K22) -> MAT021 | B23: =IF(listes!L22="","",listes!L22) -> sciences de l'ingénieur
A24: =IF(listes!K23="","",listes!K23) -> MAT022 | B24: =IF(listes!L23="","",listes!L23) -> HGGSP
A25: =IF(listes!K24="","",listes!K24) -> MAT023 | B25: =IF(listes!L24="","",listes!L24) -> HLP
A26: =IF(listes!K25="","",listes!K25) -> MAT024 | B26: =IF(listes!L25="","",listes!L25) -> LLCER
A27: =IF(listes!K26="","",listes!K26) -> MAT025 | B27: =IF(listes!L26="","",listes!L26) -> LLCA
A28: =IF(listes!K27="","",listes!K27) -> MAT026 | B28: =IF(listes!L27="","",listes!L27) -> Arts
A29: =IF(listes!K28="","",listes!K28) -> MAT027 | B29: =IF(listes!L28="","",listes!L28) -> éducation physique, pratiques et culture sportives
A30: =IF(listes!K29="","",listes!K29) -> MAT028 | B30: =IF(listes!L29="","",listes!L29) -> philosophie
A31: =IF(listes!K30="","",listes!K30) -> MAT029 | B31: =IF(listes!L30="","",listes!L30) -> DGEMC
A32: =IF(listes!K31="","",listes!K31) -> MAT030 | B32: =IF(listes!L31="","",listes!L31) -> latin | I32: 1 | J32: 1 | K32: 1
A33: =IF(listes!K32="","",listes!K32) -> MAT031 | B33: =IF(listes!L32="","",listes!L32) -> grec ancien | I33: 1 | J33: 1 | K33: 1
A34: =IF(listes!K33="","",listes!K33) -> MAT032 | B34: =IF(listes!L33="","",listes!L33) -> littérature française
A35: =IF(listes!K34="","",listes!K34) -> MAT033 | B35: =IF(listes!L34="","",listes!L34) -> littérature comparée
A36: =IF(listes!K35="","",listes!K35) -> MAT034 | B36: =IF(listes!L35="","",listes!L35) -> langue française et stylistique
A37: =IF(listes!K36="","",listes!K36) -> MAT035 | B37: =IF(listes!L36="","",listes!L36) -> linguistique
A38: =IF(listes!K37="","",listes!K37) -> MAT036 | B38: =IF(listes!L37="","",listes!L37) -> économie
A39: =IF(listes!K38="","",listes!K38) -> MAT037 | B39: =IF(listes!L38="","",listes!L38) -> sociologie
A40: =IF(listes!K39="","",listes!K39) -> MAT038 | B40: =IF(listes!L39="","",listes!L39) -> géopolitique
...
